{"id": "CWE-248", "description": "An exception is thrown from a function, but it is not caught.", "hackerone": {"collected_date": "2024-09-11T03:18:01Z", "total_reports": 75, "unique_reports_last_12_weeks": 8, "severity_distribution": {"all_time": {"critical": 0, "high": 0, "medium": 0, "low": 1}}, "change_distribution": {"days_past": 6, "critical": 0, "high": 0, "medium": 0, "low": 0}}, "bugcrowd": {"collected_date": "2024-09-11T03:18:01Z", "vrt_id": [], "parent_vrt_id": [], "vrt_priority": 0}}