{"id": "CWE-248", "description": "An exception is thrown from a function, but it is not caught.", "hackerone": {"collected_date": "2024-08-22T17:37:09Z", "total_reports": 72, "unique_reports_last_12_weeks": 7, "severity_distribution": {"all_time": {"critical": 0, "high": 0, "medium": 0, "low": 1}}, "change_distribution": {"days_past": 0, "critical": 0, "high": 0, "medium": 0, "low": 0}}}