{"id": "CWE-584", "description": "The code has a return statement inside a finally block, which will cause any thrown exception in the try block to be discarded.", "hackerone": {"collected_date": "2024-08-22T20:41:30Z", "total_reports": 70, "unique_reports_last_12_weeks": 4, "severity_distribution": {"all_time": {"critical": 0, "high": 0, "medium": 0, "low": 0}}, "change_distribution": {"days_past": 0, "critical": 0, "high": 0, "medium": 0, "low": 0}}, "bugcrowd": {"collected_date": "2024-08-22T20:41:30Z", "vrt_id": "unavailable"}}