{"id": "CWE-584", "description": "The code has a return statement inside a finally block, which will cause any thrown exception in the try block to be discarded.", "hackerone": {"collected_date": "2024-09-04T16:45:17Z", "total_reports": 74, "unique_reports_last_12_weeks": 5, "severity_distribution": {"all_time": {"critical": 0, "high": 0, "medium": 0, "low": 0}}, "change_distribution": {"days_past": 1, "critical": 0, "high": 0, "medium": 0, "low": 0}}, "bugcrowd": {"collected_date": "2024-09-04T16:45:17Z", "vrt_id": [], "parent_vrt_id": [], "vrt_priority": 0}}